<?xml version="1.0" ?>
<robot name="spotURDF" xmlns:xacro="http://www.ros.org/wiki/xacro">

<xacro:include filename="$(find spotURDF_description)/urdf/materials.xacro" />
<xacro:include filename="$(find spotURDF_description)/urdf/spotURDF.trans" />
<xacro:include filename="$(find spotURDF_description)/urdf/spotURDF.gazebo" />
<link name="base_link">
  <inertial>
    <origin rpy="0 0 0" xyz="0.05971230943588049 0.1915410353054319 0.10379183049192559"/>
    <mass value="0.15593839458053116"/>
    <inertia ixx="0.000385" ixy="0.0" ixz="0.0" iyy="4.8e-05" iyz="-1.2e-05" izz="0.000403"/>
  </inertial>
  <visual>
    <origin rpy="0 0 0" xyz="0 0 0"/>
    <geometry>
      <mesh filename="package://spotURDF_description/meshes/base_link.stl" scale="0.001 0.001 0.001"/>
    </geometry>
    <material name="silver"/>
  </visual>
  <collision>
    <origin rpy="0 0 0" xyz="0 0 0"/>
    <geometry>
      <mesh filename="package://spotURDF_description/meshes/base_link.stl" scale="0.001 0.001 0.001"/>
    </geometry>
  </collision>
</link>

<link name="servo_1">
  <inertial>
    <origin rpy="0 0 0" xyz="-0.004038544658970675 0.013204850014472719 -0.00022426075196999018"/>
    <mass value="0.010362264661810883"/>
    <inertia ixx="1e-06" ixy="0.0" ixz="0.0" iyy="1e-06" iyz="-0.0" izz="1e-06"/>
  </inertial>
  <visual>
    <origin rpy="0 0 0" xyz="-0.07692 -0.129093 -0.105972"/>
    <geometry>
      <mesh filename="package://spotURDF_description/meshes/servo_1.stl" scale="0.001 0.001 0.001"/>
    </geometry>
    <material name="silver"/>
  </visual>
  <collision>
    <origin rpy="0 0 0" xyz="-0.07692 -0.129093 -0.105972"/>
    <geometry>
      <mesh filename="package://spotURDF_description/meshes/servo_1.stl" scale="0.001 0.001 0.001"/>
    </geometry>
  </collision>
</link>

<link name="servo__3__1">
  <inertial>
    <origin rpy="0 0 0" xyz="-0.004038365236444921 0.013205437003384363 -0.00022426047629711676"/>
    <mass value="0.010362264661810883"/>
    <inertia ixx="1e-06" ixy="0.0" ixz="0.0" iyy="1e-06" iyz="-0.0" izz="1e-06"/>
  </inertial>
  <visual>
    <origin rpy="0 0 0" xyz="-0.07696 -0.24309 -0.106709"/>
    <geometry>
      <mesh filename="package://spotURDF_description/meshes/servo__3__1.stl" scale="0.001 0.001 0.001"/>
    </geometry>
    <material name="silver"/>
  </visual>
  <collision>
    <origin rpy="0 0 0" xyz="-0.07696 -0.24309 -0.106709"/>
    <geometry>
      <mesh filename="package://spotURDF_description/meshes/servo__3__1.stl" scale="0.001 0.001 0.001"/>
    </geometry>
  </collision>
</link>

<link name="servo__1__1">
  <inertial>
    <origin rpy="0 0 0" xyz="0.004038365889253284 0.013204850014472663 0.0002247877672378884"/>
    <mass value="0.010362264661810883"/>
    <inertia ixx="1e-06" ixy="-0.0" ixz="0.0" iyy="1e-06" iyz="0.0" izz="1e-06"/>
  </inertial>
  <visual>
    <origin rpy="0 0 0" xyz="-0.04282 -0.129093 -0.105972"/>
    <geometry>
      <mesh filename="package://spotURDF_description/meshes/servo__1__1.stl" scale="0.001 0.001 0.001"/>
    </geometry>
    <material name="silver"/>
  </visual>
  <collision>
    <origin rpy="0 0 0" xyz="-0.04282 -0.129093 -0.105972"/>
    <geometry>
      <mesh filename="package://spotURDF_description/meshes/servo__1__1.stl" scale="0.001 0.001 0.001"/>
    </geometry>
  </collision>
</link>

<link name="servo__2__1">
  <inertial>
    <origin rpy="0 0 0" xyz="0.004038365889253395 0.013205437003384474 0.00022478804291048426"/>
    <mass value="0.010362264661810883"/>
    <inertia ixx="1e-06" ixy="-0.0" ixz="0.0" iyy="1e-06" iyz="0.0" izz="1e-06"/>
  </inertial>
  <visual>
    <origin rpy="0 0 0" xyz="-0.04272 -0.24309 -0.106709"/>
    <geometry>
      <mesh filename="package://spotURDF_description/meshes/servo__2__1.stl" scale="0.001 0.001 0.001"/>
    </geometry>
    <material name="silver"/>
  </visual>
  <collision>
    <origin rpy="0 0 0" xyz="-0.04272 -0.24309 -0.106709"/>
    <geometry>
      <mesh filename="package://spotURDF_description/meshes/servo__2__1.stl" scale="0.001 0.001 0.001"/>
    </geometry>
  </collision>
</link>

<link name="fr_leg_1">
  <inertial>
    <origin rpy="0 0 0" xyz="-0.005828531513050319 0.014049939833651048 -0.027769452214174692"/>
    <mass value="0.02306397378886889"/>
    <inertia ixx="2.3e-05" ixy="-0.0" ixz="-0.0" iyy="1.8e-05" iyz="1e-06" izz="6e-06"/>
  </inertial>
  <visual>
    <origin rpy="0 0 0" xyz="-0.03204 -0.13723 -0.106196"/>
    <geometry>
      <mesh filename="package://spotURDF_description/meshes/fr_leg_1.stl" scale="0.001 0.001 0.001"/>
    </geometry>
    <material name="silver"/>
  </visual>
  <collision>
    <origin rpy="0 0 0" xyz="-0.03204 -0.13723 -0.106196"/>
    <geometry>
      <mesh filename="package://spotURDF_description/meshes/fr_leg_1.stl" scale="0.001 0.001 0.001"/>
    </geometry>
  </collision>
</link>

<link name="fl_leg_1">
  <inertial>
    <origin rpy="0 0 0" xyz="0.005828352048753149 0.013044620216436043 -0.0282560129079764"/>
    <mass value="0.02306393986938087"/>
    <inertia ixx="2.3e-05" ixy="0.0" ixz="0.0" iyy="1.8e-05" iyz="0.0" izz="6e-06"/>
  </inertial>
  <visual>
    <origin rpy="0 0 0" xyz="-0.0877 -0.13723 -0.105748"/>
    <geometry>
      <mesh filename="package://spotURDF_description/meshes/fl_leg_1.stl" scale="0.001 0.001 0.001"/>
    </geometry>
    <material name="silver"/>
  </visual>
  <collision>
    <origin rpy="0 0 0" xyz="-0.0877 -0.13723 -0.105748"/>
    <geometry>
      <mesh filename="package://spotURDF_description/meshes/fl_leg_1.stl" scale="0.001 0.001 0.001"/>
    </geometry>
  </collision>
</link>

<link name="fl_leg__1__1">
  <inertial>
    <origin rpy="0 0 0" xyz="0.005828531471279166 0.014739240692406896 -0.02741050389011923"/>
    <mass value="0.02306393986938087"/>
    <inertia ixx="2.3e-05" ixy="0.0" ixz="0.0" iyy="1.7e-05" iyz="1e-06" izz="6e-06"/>
  </inertial>
  <visual>
    <origin rpy="0 0 0" xyz="-0.08774 -0.251227 -0.106485"/>
    <geometry>
      <mesh filename="package://spotURDF_description/meshes/fl_leg__1__1.stl" scale="0.001 0.001 0.001"/>
    </geometry>
    <material name="silver"/>
  </visual>
  <collision>
    <origin rpy="0 0 0" xyz="-0.08774 -0.251227 -0.106485"/>
    <geometry>
      <mesh filename="package://spotURDF_description/meshes/fl_leg__1__1.stl" scale="0.001 0.001 0.001"/>
    </geometry>
  </collision>
</link>

<link name="rr_leg_1">
  <inertial>
    <origin rpy="0 0 0" xyz="-0.005828531513050374 0.013172479995305464 -0.028196535474165382"/>
    <mass value="0.02306397378886889"/>
    <inertia ixx="2.3e-05" ixy="-0.0" ixz="-0.0" iyy="1.8e-05" iyz="0.0" izz="6e-06"/>
  </inertial>
  <visual>
    <origin rpy="0 0 0" xyz="-0.03194 -0.251227 -0.106933"/>
    <geometry>
      <mesh filename="package://spotURDF_description/meshes/rr_leg_1.stl" scale="0.001 0.001 0.001"/>
    </geometry>
    <material name="silver"/>
  </visual>
  <collision>
    <origin rpy="0 0 0" xyz="-0.03194 -0.251227 -0.106933"/>
    <geometry>
      <mesh filename="package://spotURDF_description/meshes/rr_leg_1.stl" scale="0.001 0.001 0.001"/>
    </geometry>
  </collision>
</link>

<link name="lid_1">
  <inertial>
    <origin rpy="0 0 0" xyz="0.0152823789173697 -0.03282391466918336 0.0010028365291432084"/>
    <mass value="0.01247391983033411"/>
    <inertia ixx="1.2e-05" ixy="-0.0" ixz="0.0" iyy="1e-06" iyz="0.0" izz="1.3e-05"/>
  </inertial>
  <visual>
    <origin rpy="0 0 0" xyz="-0.04454 -0.23975 -0.119878"/>
    <geometry>
      <mesh filename="package://spotURDF_description/meshes/lid_1.stl" scale="0.001 0.001 0.001"/>
    </geometry>
    <material name="silver"/>
  </visual>
  <collision>
    <origin rpy="0 0 0" xyz="-0.04454 -0.23975 -0.119878"/>
    <geometry>
      <mesh filename="package://spotURDF_description/meshes/lid_1.stl" scale="0.001 0.001 0.001"/>
    </geometry>
  </collision>
</link>

<joint name="Rigid1" type="fixed">
  <origin rpy="0 0 0" xyz="0.07692 0.129093 0.105972"/>
  <parent link="base_link"/>
  <child link="servo_1"/>
</joint>

<joint name="Rigid2" type="fixed">
  <origin rpy="0 0 0" xyz="0.07696 0.24309 0.106709"/>
  <parent link="base_link"/>
  <child link="servo__3__1"/>
</joint>

<joint name="Rigid3" type="fixed">
  <origin rpy="0 0 0" xyz="0.04282 0.129093 0.105972"/>
  <parent link="base_link"/>
  <child link="servo__1__1"/>
</joint>

<joint name="Rigid4" type="fixed">
  <origin rpy="0 0 0" xyz="0.04272 0.24309 0.106709"/>
  <parent link="base_link"/>
  <child link="servo__2__1"/>
</joint>

<joint name="Rev5" type="revolute">
  <origin rpy="0 0 0" xyz="-0.01078 0.008137 0.000224"/>
  <parent link="servo__1__1"/>
  <child link="fr_leg_1"/>
  <axis xyz="-1.0 -0.0 0.0"/>
  <limit effort="100" lower="-1.745329" upper="2.007129" velocity="100"/>
</joint>

<joint name="Rev6" type="revolute">
  <origin rpy="0 0 0" xyz="0.01078 0.008137 -0.000224"/>
  <parent link="servo_1"/>
  <child link="fl_leg_1"/>
  <axis xyz="1.0 -0.0 -0.0"/>
  <limit effort="100" lower="-2.007129" upper="1.745329" velocity="100"/>
</joint>

<joint name="Rev7" type="revolute">
  <origin rpy="0 0 0" xyz="0.01078 0.008137 -0.000224"/>
  <parent link="servo__3__1"/>
  <child link="fl_leg__1__1"/>
  <axis xyz="1.0 -0.0 0.0"/>
  <limit effort="100" lower="-1.745329" upper="2.268928" velocity="100"/>
</joint>

<joint name="Rev8" type="revolute">
  <origin rpy="0 0 0" xyz="-0.01078 0.008137 0.000224"/>
  <parent link="servo__2__1"/>
  <child link="rr_leg_1"/>
  <axis xyz="-1.0 -0.0 -0.0"/>
  <limit effort="100" lower="-2.268928" upper="1.745329" velocity="100"/>
</joint>

<joint name="Rigid9" type="fixed">
  <origin rpy="0 0 0" xyz="0.04454 0.23975 0.119878"/>
  <parent link="base_link"/>
  <child link="lid_1"/>
</joint>

</robot>
