#VRML_SIM R2021b utf8
WorldInfo {
  basicTimeStep 0.01
  FPS 40
  coordinateSystem "NUE"
}
Viewpoint {
  orientation 0.09152557008365174 0.9823522930564517 0.1631166525759837 4.496920866978151
  position -0.16010302976844623 0.10397369509765603 0.10559633089584931
}
TexturedBackground {
}
TexturedBackgroundLight {
}
RectangleArena {
  floorTileSize 0.17 0.17
}
Robot {
  translation 0 -3e-07 0.22
  rotation 1 0 0 -1.5707953071795862
  scale 0.0005 0.0005 0.0005
  children [
    Shape {
      appearance PBRAppearance {
        baseColor 0.5 0.5 0.5
        roughness 1
        metalness 0
      }
      geometry DEF base_link Mesh {
        url [
          "../protos/spotURDF_description/meshes/base_link.stl"
        ]
      }
    }
    Solid {
      translation 0.07692 0.1290929999999248 0.10597199999998384
      rotation -0.5099991019978639 -0.8526498973309489 -0.11353003366023702 3.700749931655117e-15
      children [
        Transform {
          translation -0.07692 -0.129093 -0.105972
          children [
            Shape {
              appearance PBRAppearance {
                baseColor 0.5 0.5 0.5
                roughness 1
                metalness 0
              }
              geometry DEF servo_1 Mesh {
                url [
                  "../protos/spotURDF_description/meshes/servo_1.stl"
                ]
              }
            }
          ]
        }
        HingeJoint {
          jointParameters HingeJointParameters {
            position -5.329070518200751e-15
            anchor 0.01078 0.008137 -0.000224
          }
          device [
            RotationalMotor {
              name "Rev6"
              maxVelocity 100
              minPosition -2.007129
              maxPosition 1.745329
              maxTorque 100
            }
            PositionSensor {
              name "Rev6_sensor"
            }
          ]
          endPoint Solid {
            translation 0.0107800000000001 0.008137000000391689 -0.00022400000008072213
            rotation 1 0 0 0
            children [
              Transform {
                translation -0.0877 -0.13723 -0.105748
                children [
                  Shape {
                    appearance PBRAppearance {
                      baseColor 0.5 0.5 0.5
                      roughness 1
                      metalness 0
                    }
                    geometry DEF fl_leg_1 Mesh {
                      url [
                        "../protos/spotURDF_description/meshes/fl_leg_1.stl"
                      ]
                    }
                  }
                ]
              }
            ]
            name "fl_leg_1"
            boundingObject Transform {
              translation -0.0877 -0.13723 -0.105748
              children [
                USE fl_leg_1
              ]
            }
            physics Physics {
              density -1
              mass 0.023064
              centerOfMass [
                0.005828 0.013045 -0.028256
              ]
              inertiaMatrix [
                2.3e-05 1.8e-05 6e-06
                0 0 0
              ]
            }
          }
        }
      ]
      name "servo_1"
      boundingObject Transform {
        translation -0.07692 -0.129093 -0.105972
        children [
          USE servo_1
        ]
      }
      physics Physics {
        density -1
        mass 0.5
        centerOfMass [
          -0.004039 0.013205 -0.000224
        ]
        inertiaMatrix [
          1e-06 1e-06 1e-06
          0 0 0
        ]
      }
    }
    Solid {
      translation 0.07696 0.24308999999999703 0.10670899999998375
      rotation 0.35817765928445033 -0.925456612835247 -0.12344562426033563 3.409607761487458e-15
      children [
        Transform {
          translation -0.07696 -0.24309 -0.106709
          children [
            Shape {
              appearance PBRAppearance {
                baseColor 0.5 0.5 0.5
                roughness 1
                metalness 0
              }
              geometry DEF servo__3__1 Mesh {
                url [
                  "../protos/spotURDF_description/meshes/servo__3__1.stl"
                ]
              }
            }
          ]
        }
        HingeJoint {
          jointParameters HingeJointParameters {
            position -1.509903313490213e-14
            anchor 0.01078 0.008137 -0.000224
          }
          device [
            RotationalMotor {
              name "Rev7"
              maxVelocity 100
              minPosition -1.745329
              maxPosition 2.268928
              maxTorque 100
            }
            PositionSensor {
              name "Rev7_sensor"
            }
          ]
          endPoint Solid {
            translation 0.010780000000000471 0.008137000000012218 -0.00022400000102939903
            rotation 1 0 0 0
            children [
              Transform {
                translation -0.08774 -0.251227 -0.106485
                children [
                  Shape {
                    appearance PBRAppearance {
                      baseColor 0.5 0.5 0.5
                      roughness 1
                      metalness 0
                    }
                    geometry DEF fl_leg__1__1 Mesh {
                      url [
                        "../protos/spotURDF_description/meshes/fl_leg__1__1.stl"
                      ]
                    }
                  }
                ]
              }
            ]
            name "fl_leg__1__1"
            boundingObject Transform {
              translation -0.08774 -0.251227 -0.106485
              children [
                USE fl_leg__1__1
              ]
            }
            physics Physics {
              density -1
              mass 0.023064
              centerOfMass [
                0.005829 0.014739 -0.027411
              ]
              inertiaMatrix [
                2.3e-05 1.7e-05 6e-06
                0 0 1e-06
              ]
            }
          }
        }
      ]
      name "servo__3__1"
      boundingObject Transform {
        translation -0.07696 -0.24309 -0.106709
        children [
          USE servo__3__1
        ]
      }
      physics Physics {
        density -1
        mass 0.5
        centerOfMass [
          -0.004038 0.013205 -0.000224
        ]
        inertiaMatrix [
          1e-06 1e-06 1e-06
          0 0 0
        ]
      }
    }
    Solid {
      translation 0.04281999999999999 0.1290929999999248 0.10597199999998373
      rotation 0.897594206497358 -4.494695602854178e-07 -0.44082268596588386 1.3605762138921145e-15
      children [
        Transform {
          translation -0.04282 -0.129093 -0.105972
          children [
            Shape {
              appearance PBRAppearance {
                baseColor 0.5 0.5 0.5
                roughness 1
                metalness 0
              }
              geometry DEF servo__1__1 Mesh {
                url [
                  "../protos/spotURDF_description/meshes/servo__1__1.stl"
                ]
              }
            }
          ]
        }
        HingeJoint {
          jointParameters HingeJointParameters {
            position -1.7763568394002505e-15
            axis -1 0 0
            anchor -0.01078 0.008137 0.000224
          }
          device [
            RotationalMotor {
              name "Rev5"
              maxVelocity 100
              minPosition -1.745329
              maxPosition 2.007129
              maxTorque 100
            }
            PositionSensor {
              name "Rev5_sensor"
            }
          ]
          endPoint Solid {
            translation -0.010779999999999809 0.008136999999795377 0.00022399999910494017
            rotation -1 0 0 0
            children [
              Transform {
                translation -0.03204 -0.13723 -0.106196
                children [
                  Shape {
                    appearance PBRAppearance {
                      baseColor 0.5 0.5 0.5
                      roughness 1
                      metalness 0
                    }
                    geometry DEF fr_leg_1 Mesh {
                      url [
                        "../protos/spotURDF_description/meshes/fr_leg_1.stl"
                      ]
                    }
                  }
                ]
              }
            ]
            name "fr_leg_1"
            boundingObject Transform {
              translation -0.03204 -0.13723 -0.106196
              children [
                USE fr_leg_1
              ]
            }
            physics Physics {
              density -1
              mass 0.023064
              centerOfMass [
                -0.005829 0.01405 -0.027769
              ]
              inertiaMatrix [
                2.3e-05 1.8e-05 6e-06
                0 0 1e-06
              ]
            }
          }
        }
      ]
      name "servo__1__1"
      boundingObject Transform {
        translation -0.04282 -0.129093 -0.105972
        children [
          USE servo__1__1
        ]
      }
      physics Physics {
        density -1
        mass 0.5
        centerOfMass [
          0.004038 0.013205 0.000225
        ]
        inertiaMatrix [
          1e-06 1e-06 1e-06
          0 0 0
        ]
      }
    }
    Solid {
      translation 0.042719999999999994 0.24308999999999703 0.10670899999998378
      rotation 0.3561565223351809 0.8435476892752152 -0.40196993359771926 1.8703400696062266e-15
      children [
        Solid {
          children [
            Shape {
              appearance PBRAppearance {
                baseColor 0.5 0.5 0.5
                roughness 1
                metalness 0
              }
              geometry DEF servo__2__1 Mesh {
                url [
                  "../protos/spotURDF_description/meshes/servo__2__1.stl"
                ]
              }
            }
          ]
        }
        HingeJoint {
          jointParameters HingeJointParameters {
            position 5.738369331424743e-15
            axis -1 0 0
            anchor -0.01078 0.008137 0.000224
          }
          device [
            RotationalMotor {
              name "Rev8"
              maxVelocity 100
              minPosition -2.268928
              maxPosition 1.745329
              maxTorque 100
            }
            PositionSensor {
              name "Rev8_sensor"
            }
          ]
          endPoint Solid {
            translation -0.010779999999999802 0.008136999999795377 0.00022400000040598278
            rotation -1 0 0 0
            children [
              Transform {
                translation -0.03194 -0.251227 -0.106933
                children [
                  Shape {
                    appearance PBRAppearance {
                      baseColor 0.5 0.5 0.5
                      roughness 1
                      metalness 0
                    }
                    geometry DEF rr_leg_1 Mesh {
                      url [
                        "../protos/spotURDF_description/meshes/rr_leg_1.stl"
                      ]
                    }
                  }
                ]
              }
            ]
            name "rr_leg_1"
            boundingObject Transform {
              translation -0.03194 -0.251227 -0.106933
              children [
                USE rr_leg_1
              ]
            }
            physics Physics {
              density -1
              mass 0.023064
              centerOfMass [
                -0.005829 0.013172 -0.028197
              ]
              inertiaMatrix [
                2.3e-05 1.8e-05 6e-06
                0 0 0
              ]
            }
          }
        }
      ]
      name "servo__2__1"
      boundingObject Transform {
        translation -0.04272 -0.24309 -0.106709
        children [
          USE servo__2__1
        ]
      }
      physics Physics {
        density -1
        mass 0.5
        centerOfMass [
          0.004038 0.013205 0.000225
        ]
        inertiaMatrix [
          1e-06 1e-06 1e-06
          0 0 0
        ]
      }
    }
  ]
  name "SpotURDF"
  boundingObject USE base_link
  physics Physics {
    density 1
    mass 1
  }
}
