#VRML_SIM R2021b utf8
WorldInfo {
  basicTimeStep 50
  FPS 50
  optimalThreadCount 4
  coordinateSystem "NUE"
}
Viewpoint {
  orientation -0.3403271479040685 -0.9295236303351636 -0.14199736986303776 0.7951476065715016
  position -0.18728531174247828 0.13669990333314824 0.13815782393878323
}
TexturedBackground {
}
TexturedBackgroundLight {
}
Floor {
  size 1 1
  tileSize 0.18 0.18
}
Robot {
  translation 1.49637e-35 -0.004525 2.03924e-08
  rotation 1 2.33993e-34 9.82178e-34 -1.5707953071795862
  scale 0.0005 0.0005 0.0005
  children [
    Shape {
      appearance PBRAppearance {
        baseColor 0.5 0.5 0.5
        roughness 1
        metalness 0
      }
      geometry DEF base_link Mesh {
        url [
          "C:/Users/Martin/Desktop/Boston-Dynamics-Ultra-Micro-Spot-Desk-Pet-/3D Webots/protos/base_link.stl"
        ]
      }
    }
    Solid {
      translation 0.07692 0.129093 0.105972
      children [
        Transform {
          translation -0.07692 -0.129093 -0.105972
          children [
            Shape {
              appearance PBRAppearance {
                baseColor 0.5 0.5 0.5
                roughness 1
                metalness 0
              }
              geometry DEF servo_1 Mesh {
                url [
                  "C:/Users/Martin/Desktop/Boston-Dynamics-Ultra-Micro-Spot-Desk-Pet-/3D Webots/protos/servo_1.stl"
                ]
              }
            }
          ]
        }
        HingeJoint {
          jointParameters HingeJointParameters {
            anchor 0.01078 0.008137 -0.000224
          }
          device [
            RotationalMotor {
              name "Rev6"
              maxVelocity 100
              minPosition -2.007129
              maxPosition 1.745329
              maxTorque 100
            }
            PositionSensor {
              name "Rev6_sensor"
            }
          ]
          endPoint Solid {
            translation 0.010780000000000034 0.008137000000005097 -0.00022400000001634762
            rotation -0.9933273440620319 -0.027480073406798974 0.11200729040659153 3.4536340578957205e-14
            children [
              Transform {
                translation -0.0877 -0.13723 -0.105748
                children [
                  Shape {
                    appearance PBRAppearance {
                      baseColor 0.5 0.5 0.5
                      roughness 1
                      metalness 0
                    }
                    geometry DEF fl_leg_1 Mesh {
                      url [
                        "C:/Users/Martin/Desktop/Boston-Dynamics-Ultra-Micro-Spot-Desk-Pet-/3D Webots/protos/fl_leg_1.stl"
                      ]
                    }
                  }
                ]
              }
            ]
            name "fl_leg_1"
            boundingObject Transform {
              translation -0.0877 -0.13723 -0.105748
              children [
                USE fl_leg_1
              ]
            }
            physics Physics {
              density -1
              mass 0.023064
              centerOfMass [
                0.005828 0.013045 -0.028256
              ]
              inertiaMatrix [
                2.3e-05 1.8e-05 6e-06
                0 0 0
              ]
            }
          }
        }
      ]
      name "servo_1"
      boundingObject Transform {
        translation -0.07692 -0.129093 -0.105972
        children [
          USE servo_1
        ]
      }
      physics Physics {
        density -1
        mass 0.010362
        centerOfMass [
          -0.004039 0.013205 -0.000224
        ]
        inertiaMatrix [
          1e-06 1e-06 1e-06
          0 0 0
        ]
      }
    }
    Solid {
      translation 0.07696 0.24309 0.106709
      children [
        Transform {
          translation -0.07696 -0.24309 -0.106709
          children [
            Shape {
              appearance PBRAppearance {
                baseColor 0.5 0.5 0.5
                roughness 1
                metalness 0
              }
              geometry DEF servo__3__1 Mesh {
                url [
                  "C:/Users/Martin/Desktop/Boston-Dynamics-Ultra-Micro-Spot-Desk-Pet-/3D Webots/protos/servo__3__1.stl"
                ]
              }
            }
          ]
        }
        HingeJoint {
          jointParameters HingeJointParameters {
            anchor 0.01078 0.008137 -0.000224
          }
          device [
            RotationalMotor {
              name "Rev7"
              maxVelocity 100
              minPosition -1.745329
              maxPosition 2.268928
              maxTorque 100
            }
            PositionSensor {
              name "Rev7_sensor"
            }
          ]
          endPoint Solid {
            translation 0.010780000000000048 0.008137000000005125 -0.00022400000003328828
            rotation -0.9933273440613637 -0.027480073403136646 0.11200729041341571 3.4536340578980435e-14
            children [
              Transform {
                translation -0.08774 -0.251227 -0.106485
                children [
                  Shape {
                    appearance PBRAppearance {
                      baseColor 0.5 0.5 0.5
                      roughness 1
                      metalness 0
                    }
                    geometry DEF fl_leg__1__1 Mesh {
                      url [
                        "C:/Users/Martin/Desktop/Boston-Dynamics-Ultra-Micro-Spot-Desk-Pet-/3D Webots/protos/fl_leg__1__1.stl"
                      ]
                    }
                  }
                ]
              }
            ]
            name "fl_leg__1__1"
            boundingObject Transform {
              translation -0.08774 -0.251227 -0.106485
              children [
                USE fl_leg__1__1
              ]
            }
            physics Physics {
              density -1
              mass 0.023064
              centerOfMass [
                0.005829 0.014739 -0.027411
              ]
              inertiaMatrix [
                2.3e-05 1.7e-05 6e-06
                0 0 1e-06
              ]
            }
          }
        }
      ]
      name "servo__3__1"
      boundingObject Transform {
        translation -0.07696 -0.24309 -0.106709
        children [
          USE servo__3__1
        ]
      }
      physics Physics {
        density -1
        mass 0.010362
        centerOfMass [
          -0.004038 0.013205 -0.000224
        ]
        inertiaMatrix [
          1e-06 1e-06 1e-06
          0 0 0
        ]
      }
    }
    Solid {
      translation 0.04282 0.129093 0.105972
      children [
        Transform {
          translation -0.04282 -0.129093 -0.105972
          children [
            Shape {
              appearance PBRAppearance {
                baseColor 0.5 0.5 0.5
                roughness 1
                metalness 0
              }
              geometry DEF servo__1__1 Mesh {
                url [
                  "C:/Users/Martin/Desktop/Boston-Dynamics-Ultra-Micro-Spot-Desk-Pet-/3D Webots/protos/servo__1__1.stl"
                ]
              }
            }
          ]
        }
        HingeJoint {
          jointParameters HingeJointParameters {
            axis -1 0 0
            anchor -0.01078 0.008137 0.000224
          }
          device [
            RotationalMotor {
              name "Rev5"
              maxVelocity 100
              minPosition -1.745329
              maxPosition 2.007129
              maxTorque 100
            }
            PositionSensor {
              name "Rev5_sensor"
            }
          ]
          endPoint Solid {
            translation -0.010779999999999935 0.008137000000005097 0.0002239999999824663
            rotation -0.9933273440616592 -0.027480073401991573 0.11200729041107547 3.453634057897016e-14
            children [
              Transform {
                translation -0.03204 -0.13723 -0.106196
                children [
                  Shape {
                    appearance PBRAppearance {
                      baseColor 0.5 0.5 0.5
                      roughness 1
                      metalness 0
                    }
                    geometry DEF fr_leg_1 Mesh {
                      url [
                        "C:/Users/Martin/Desktop/Boston-Dynamics-Ultra-Micro-Spot-Desk-Pet-/3D Webots/protos/fr_leg_1.stl"
                      ]
                    }
                  }
                ]
              }
            ]
            name "fr_leg_1"
            boundingObject Transform {
              translation -0.03204 -0.13723 -0.106196
              children [
                USE fr_leg_1
              ]
            }
            physics Physics {
              density -1
              mass 0.023064
              centerOfMass [
                -0.005829 0.01405 -0.027769
              ]
              inertiaMatrix [
                2.3e-05 1.8e-05 6e-06
                0 0 1e-06
              ]
            }
          }
        }
      ]
      name "servo__1__1"
      boundingObject Transform {
        translation -0.04282 -0.129093 -0.105972
        children [
          USE servo__1__1
        ]
      }
      physics Physics {
        density -1
        mass 0.010362
        centerOfMass [
          0.004038 0.013205 0.000225
        ]
        inertiaMatrix [
          1e-06 1e-06 1e-06
          0 0 0
        ]
      }
    }
    Solid {
      translation 0.04272 0.24309 0.106709
      children [
        Transform {
          translation -0.04272 -0.24309 -0.106709
          children [
            Shape {
              appearance PBRAppearance {
                baseColor 0.5 0.5 0.5
                roughness 1
                metalness 0
              }
              geometry DEF servo__2__1 Mesh {
                url [
                  "C:/Users/Martin/Desktop/Boston-Dynamics-Ultra-Micro-Spot-Desk-Pet-/3D Webots/protos/servo__2__1.stl"
                ]
              }
            }
          ]
        }
        HingeJoint {
          jointParameters HingeJointParameters {
            axis -1 0 0
            anchor -0.01078 0.008137 0.000224
          }
          device [
            RotationalMotor {
              name "Rev8"
              maxVelocity 100
              minPosition -2.268928
              maxPosition 1.745329
              maxTorque 100
            }
            PositionSensor {
              name "Rev8_sensor"
            }
          ]
          endPoint Solid {
            translation -0.010779999999999929 0.008137000000005177 0.0002239999999824663
            rotation -0.9933273440623734 -0.027480073404935853 0.1120072904040191 3.453634057894533e-14
            children [
              Transform {
                translation -0.03194 -0.251227 -0.106933
                children [
                  Shape {
                    appearance PBRAppearance {
                      baseColor 0.5 0.5 0.5
                      roughness 1
                      metalness 0
                    }
                    geometry DEF rr_leg_1 Mesh {
                      url [
                        "C:/Users/Martin/Desktop/Boston-Dynamics-Ultra-Micro-Spot-Desk-Pet-/3D Webots/protos/rr_leg_1.stl"
                      ]
                    }
                  }
                ]
              }
            ]
            name "rr_leg_1"
            boundingObject Transform {
              translation -0.03194 -0.251227 -0.106933
              children [
                USE rr_leg_1
              ]
            }
            physics Physics {
              density -1
              mass 0.023064
              centerOfMass [
                -0.005829 0.013172 -0.028197
              ]
              inertiaMatrix [
                2.3e-05 1.8e-05 6e-06
                0 0 0
              ]
            }
          }
        }
      ]
      name "servo__2__1"
      boundingObject Transform {
        translation -0.04272 -0.24309 -0.106709
        children [
          USE servo__2__1
        ]
      }
      physics Physics {
        density -1
        mass 0.010362
        centerOfMass [
          0.004038 0.013205 0.000225
        ]
        inertiaMatrix [
          1e-06 1e-06 1e-06
          0 0 0
        ]
      }
    }
    Solid {
      translation 0.04454 0.23975 0.119878
      children [
        Transform {
          translation -0.04454 -0.23975 -0.119878
          children [
            Shape {
              appearance PBRAppearance {
                baseColor 0.5 0.5 0.5
                roughness 1
                metalness 0
              }
              geometry DEF lid_1 Mesh {
                url [
                  "C:/Users/Martin/Desktop/Boston-Dynamics-Ultra-Micro-Spot-Desk-Pet-/3D Webots/protos/lid_1.stl"
                ]
              }
            }
          ]
        }
      ]
      name "lid_1"
      boundingObject Transform {
        translation -0.04454 -0.23975 -0.119878
        children [
          USE lid_1
        ]
      }
      physics Physics {
        density -1
        mass 0.012474
        centerOfMass [
          0.015282 -0.032824 0.001003
        ]
        inertiaMatrix [
          1.2e-05 1e-06 1.3e-05
          0 0 0
        ]
      }
    }
  ]
  name "spotURDF_converted"
  boundingObject USE base_link
  physics Physics {
    density -1
    mass 0.155938
    centerOfMass [
      0.059712 0.191541 0.103792
    ]
    inertiaMatrix [
      0.000385 4.8e-05 0.000403
      0 0 -1.2e-05
    ]
  }
}
